Workbook

Sheet Sheet2
A1: 予定日 | B1: ﾗｲﾝ | C1: SD製番 | D1: 受注件名 | E1: ﾌﾛｱ | F1: 建具符号 | G1: 区分 | H1: 区分 | I1: 区分 | J1: 数量 | K1: 開始 | L1: 終了 | M1: 備考 | N1: 金額
A2: 46258 | B2: 前組2 | C2: S2602671 | D2: 所沢市小手指一丁目計画 | E2: 1F | F2: SD-115 | G2: 親 | H2: 枠 | I2: R | J2: 1 | K2: 8:40 | L2: 11:05 | M2: 曲げ遅れにより中断
A3: 46258 | B3: 前組2 | C3: S2602671 | D3: 所沢市小手指一丁目計画 | E3: 3F | F3: SD-301 | G3: 親 | H3: 枠 | I3: L | J3: 1 | K3: 11:25 | L3: 14:25 | M3: 曲げ遅れにより中断
A4: 46258 | B4: 前組2 | C4: S2602674 | D4: 特別養護老人ホーム | E4: 2F | F4: SD-31-1 | G4: 親 | H4: 枠 | I4: R | J4: 1 | K4: 14:45 | L4: 15:30 | M4: 作業者に指示出し等で段取り時間増 | N4: 15600
A5: 46258 | B5: 前組2 | C5: S2602671 | D5: 所沢市小手指一丁目計画 | E5: 1F | F5: SD-115 | G5: 親 | H5: 枠 | I5: R | K5: 15:30 | L5: 15:30 | M5: 作業時間合計95分 | N5: 78000
A6: 46258 | B6: 前組2 | C6: S2602671 | D6: 所沢市小手指一丁目計画 | E6: 3F | F6: SD-301 | G6: 親 | H6: 枠 | I6: L | K6: 15:30 | L6: 15:30 | M6: 作業時間合計115分 | N6: 73800
A7: 46258 | B7: 前組2 | C7: S2602674 | D7: 特別養護老人ホーム | E7: 3F | F7: SD-31-1 | G7: 親 | H7: 枠 | I7: R | J7: 1 | K7: 15:35 | L7: 16:05 | N7: 15600
A8: 46258 | B8: 前組2 | C8: S2602674 | D8: 特別養護老人ホーム | E8: 4F | F8: SD-31-1 | G8: 親 | H8: 枠 | I8: R | J8: 1 | K8: 16:10 | L8: 16:40 | N8: 15600
A9: 46258 | B9: 前組2 | C9: S2602674 | D9: 特別養護老人ホーム | E9: 2F | F9: SD-31-4 | G9: 親 | H9: 枠 | I9: L | J9: 1 | K9: 17:00 | L9: 17:40 | M9: 森山と共同製作 作業時間合計25分 | N9: 15100
A10: 46258 | B10: 前組2 | C10: S2602674 | D10: 特別養護老人ホーム | E10: 3F | F10: SD-31-4 | G10: 親 | H10: 枠 | I10: L | J10: 1 | K10: 17:45 | L10: 18:15 | M10: 森山と共同製作 作業時間合計25分 | N10: 15100
A11: 46258 | B11: 前組2 | C11: S2602674 | D11: 特別養護老人ホーム | E11: 4F | F11: SD-31-4 | G11: 親 | H11: 枠 | I11: L | J11: 1 | K11: 18:20 | L11: 18:50 | M11: 森山へ | N11: 15100
A12: 46258 | B12: 前組4 | C12: S2602674 | D12: 特別養護老人ホーム | E12: 2F | F12: SD-31 | G12: 親 | H12: 枠 | I12: R | J12: 1 | K12: 8:40 | L12: 9:30 | M12: 下枠曲げ遅れにより中断
A13: 46258 | B13: 前組4 | C13: S2602674 | D13: 特別養護老人ホーム | E13: 2F | F13: SD-31 | G13: 親 | H13: 枠 | I13: R | J13: 1 | K13: 9:35 | L13: 10:05 | M13: 下枠曲げ遅れにより中断
A14: 46258 | B14: 前組4 | C14: S2602674 | D14: 特別養護老人ホーム | E14: 2F | F14: SD-31 | G14: 親 | H14: 枠 | I14: R | J14: 1 | K14: 10:10 | L14: 10:45 | M14: 下枠曲げ遅れにより中断
A15: 46258 | B15: 前組4 | C15: S2602674 | D15: 特別養護老人ホーム | E15: 2F | F15: SD-31 | G15: 親 | H15: 枠 | I15: L | J15: 1 | K15: 10:50 | L15: 11:20 | M15: 下枠曲げ遅れにより中断
A16: 46258 | B16: 前組4 | C16: S2602674 | D16: 特別養護老人ホーム | E16: 3F | F16: SD-31 | G16: 親 | H16: 枠 | I16: R | J16: 1 | K16: 11:25 | L16: 11:55 | M16: 下枠曲げ遅れにより中断
A17: 46258 | B17: 前組4 | C17: S2602674 | D17: 特別養護老人ホーム | E17: 3F | F17: SD-31 | G17: 親 | H17: 枠 | I17: R | J17: 1 | K17: 12:00 | L17: 13:30 | M17: 下枠曲げ遅れにより中断
A18: 46258 | B18: 前組4 | C18: S2602674 | D18: 特別養護老人ホーム | E18: 3F | F18: SD-31 | G18: 親 | H18: 枠 | I18: R | J18: 1 | K18: 13:35 | L18: 14:05 | M18: 下枠曲げ遅れにより中断
A19: 46258 | B19: 前組4 | C19: S2602674 | D19: 特別養護老人ホーム | E19: 3F | F19: SD-31 | G19: 親 | H19: 枠 | I19: L | J19: 1 | K19: 14:10 | L19: 14:40 | M19: 下枠曲げ遅れにより中断
A20: 46258 | B20: 前組4 | C20: S2602674 | D20: 特別養護老人ホーム | E20: 4F | F20: SD-31 | G20: 親 | H20: 枠 | I20: R | J20: 1 | K20: 14:45 | L20: 15:30 | M20: 下枠曲げ遅れにより中断
A21: 46258 | B21: 前組4 | C21: S2602674 | D21: 特別養護老人ホーム | E21: 4F | F21: SD-31 | G21: 親 | H21: 枠 | I21: R | J21: 1 | K21: 15:35 | L21: 16:05 | M21: 下枠曲げ遅れにより中断
A22: 46258 | B22: 前組4 | C22: S2602674 | D22: 特別養護老人ホーム | E22: 4F | F22: SD-31 | G22: 親 | H22: 枠 | I22: R | J22: 1 | K22: 16:10 | L22: 16:40 | M22: 下枠曲げ遅れにより中断
A23: 46258 | B23: 前組4 | C23: S2602674 | D23: 特別養護老人ホーム | E23: 4F | F23: SD-31 | G23: 親 | H23: 枠 | I23: L | J23: 1 | K23: 16:45 | L23: 17:15 | M23: 下枠曲げ遅れにより中断
A24: 46258 | B24: 前組4 | C24: S2602674 | D24: 特別養護老人ホーム | E24: 2F | F24: SD-31 | G24: 親 | H24: 枠 | I24: R | K24: 17:15 | L24: 17:15 | M24: 作業時間合計55分 | N24: 15100
A25: 46258 | B25: 前組4 | C25: S2602674 | D25: 特別養護老人ホーム | E25: 2F | F25: SD-31 | G25: 親 | H25: 枠 | I25: R | K25: 17:15 | L25: 17:15 | M25: 作業時間合計20分 | N25: 15100
A26: 46258 | B26: 前組4 | C26: S2602674 | D26: 特別養護老人ホーム | E26: 2F | F26: SD-31 | G26: 親 | H26: 枠 | I26: R | K26: 17:15 | L26: 17:15 | M26: 作業時間合計30分 | N26: 15100
A27: 46258 | B27: 前組4 | C27: S2602674 | D27: 特別養護老人ホーム | E27: 2F | F27: SD-31 | G27: 親 | H27: 枠 | I27: L | K27: 17:15 | L27: 17:15 | M27: 作業時間合計25分 | N27: 15100
A28: 46258 | B28: 前組4 | C28: S2602674 | D28: 特別養護老人ホーム | E28: 3F | F28: SD-31 | G28: 親 | H28: 枠 | I28: R | K28: 17:15 | L28: 17:15 | M28: 作業時間合計20分 | N28: 15100
A29: 46258 | B29: 前組4 | C29: S2602674 | D29: 特別養護老人ホーム | E29: 3F | F29: SD-31 | G29: 親 | H29: 枠 | I29: R | K29: 17:15 | L29: 17:15 | M29: 作業時間合計25分 | N29: 15100
A30: 46258 | B30: 前組4 | C30: S2602674 | D30: 特別養護老人ホーム | E30: 3F | F30: SD-31 | G30: 親 | H30: 枠 | I30: R | K30: 17:15 | L30: 17:15 | M30: 作業時間合計20分 | N30: 15100
A31: 46258 | B31: 前組4 | C31: S2602674 | D31: 特別養護老人ホーム | E31: 3F | F31: SD-31 | G31: 親 | H31: 枠 | I31: L | K31: 17:15 | L31: 17:15 | M31: 作業時間合計25分 | N31: 15100
A32: 46258 | B32: 前組4 | C32: S2602674 | D32: 特別養護老人ホーム | E32: 4F | F32: SD-31 | G32: 親 | H32: 枠 | I32: R | K32: 17:15 | L32: 17:15 | M32: 作業時間合計30分 | N32: 15100
A33: 46258 | B33: 前組4 | C33: S2602674 | D33: 特別養護老人ホーム | E33: 4F | F33: SD-31 | G33: 親 | H33: 枠 | I33: R | K33: 17:15 | L33: 17:15 | M33: 作業時間合計20分 | N33: 15100
A34: 46258 | B34: 前組4 | C34: S2602674 | D34: 特別養護老人ホーム | E34: 4F | F34: SD-31 | G34: 親 | H34: 枠 | I34: R | K34: 17:15 | L34: 17:15 | M34: 作業時間合計15分 | N34: 15100
A35: 46258 | B35: 前組4 | C35: S2602674 | D35: 特別養護老人ホーム | E35: 4F | F35: SD-31 | G35: 親 | H35: 枠 | I35: L | K35: 17:15 | L35: 17:15 | M35: 作業時間合計20分 | N35: 15100
A36: 46258 | B36: 前組4 | C36: S2602592 | D36: TOK1__E__210-E520＿I | E36: 1F | F36: E01SP-1A | G36: 親 | H36: 枠 | I36: R | J36: 1 | K36: 17:35 | L36: 18:15 | N36: 33000
A37: 46258 | B37: 前組4 | C37: S2602592 | D37: TOK1__E__210-E520＿I | E37: 1F | F37: E01SP-1A | G37: 親 | H37: 枠 | I37: R | J37: 1 | K37: 18:25 | L37: 19:05 | N37: 33000
A38: 46258 | B38: 前組4 | C38: S2602674 | D38: 特別養護老人ホーム | E38: 2F | F38: SD-31-4 | G38: 親 | H38: 枠 | I38: L | K38: 19:05 | L38: 19:05 | M38: 小林分 小林と共同製作
A39: 46258 | B39: 前組4 | C39: S2602674 | D39: 特別養護老人ホーム | E39: 3F | F39: SD-31-4 | G39: 親 | H39: 枠 | I39: L | K39: 19:05 | L39: 19:05 | M39: 小林分 小林と共同製作
A40: 46258 | B40: 前組4 | C40: S2602674 | D40: 特別養護老人ホーム | E40: 4F | F40: SD-31-4 | G40: 親 | H40: 枠 | I40: L | K40: 19:05 | L40: 19:05 | M40: 小林分
...

Sheet Sheet1
A1: SchNo | B1: SchDate | C1: Line | D1: SdNo | E1: SdName | F1: Floor | G1: Symbol | H1: ItemName | I1: Qty | J1: StartTime | K1: EndTime | L1: Remark1 | M1: Remark2 | N1: ="["&_xlfn.TEXTJOIN(",",TRUE,N2:N73)&"]" -> [{"SchNo":"Q260824-0002","SchDate":"2026/08/24","Line":"前組2","SdNo":"S2602671","SdName":"所沢市小手指一丁目計画","Floor":"1F","Symbol":"SD-115","ItemName":"親 枠 R","Qty":"1","StartTime":"8:40","EndTime":"11:05","Remark1":"曲げ遅れにより中断","Remark2":""},{"SchNo":"Q260824-0003","SchDate":"2026/08/24","Line":"前組2","SdNo":"S2602671","SdName":"所沢市小手指一丁目計画","Floor":"3F","Symbol":"SD-301","ItemName":"親 枠 L","Qty":"1","StartTime":"11:25","EndTime":"14:25","Remark1":"曲げ遅れにより中断","Remark2":""},{"SchNo":"Q260824-0004","SchDate":"2026/08/24","Line":"前組2","SdNo":"S2602674","SdName":"特別養護老人ﾎｰﾑ","Floor":"2F","Symbol":"SD-31-1","ItemName":"親 枠 R","Qty":"1","StartTime":"14:45","EndTime":"15:30","Remark1":"作業者に指示出し等で段取り時間増","Remark2":"15600"},{"SchNo":"Q260824-0005","SchDate":"2026/08/24","Line":"前組2","SdNo":"S2602671","SdName":"所沢市小手指一丁目計画","Floor":"1F","Symbol":"SD-115","ItemName":"親 枠 R","Qty":"0","StartTime":"15:30","EndTime":"15:30","Remark1":"作業時間合計95分","Remark2":"78000"},{"SchNo":"Q260824-0006","SchDate":"2026/08/24","Line":"前組2","SdNo":"S2602671","SdName":"所沢市小手指一丁目計画","Floor":"3F","Symbol":"SD-301","ItemName":"親 枠 L","Qty":"0","StartTime":"15:30","EndTime":"15:30","Remark1":"作業時間合計115分","Remark2":"73800"},{"SchNo":"Q260824-0007","SchDate":"2026/08/24","Line":"前組2","SdNo":"S2602674","SdName":"特別養護老人ﾎｰﾑ","Floor":"3F","Symbol":"SD-31-1","ItemName":"親 枠 R","Qty":"1","StartTime":"15:35","EndTime":"16:05","Remark1":"","Remark2":"15600"},{"SchNo":"Q260824-0008","SchDate":"2026/08/24","Line":"前組2","SdNo":"S2602674","SdName":"特別養護老人ﾎｰﾑ","Floor":"4F","Symbol":"SD-31-1","ItemName":"親 枠 R","Qty":"1","StartTime":"16:10","EndTime":"16:40","Remark1":"","Remark2":"15600"},{"SchNo":"Q260824-0009","SchDate":"2026/08/24","Line":"前組2","SdNo":"S2602674","SdName":"特別養護老人ﾎｰﾑ","Floor":"2F","Symbol":"SD-31-4","ItemName":"親 枠 L","Qty":"1","StartTime":"17:00","EndTime":"17:40","Remark1":"森山と共同製作 作業時間合計25分","Remark2":"15100"},{"SchNo":"Q260824-0010","SchDate":"2026/08/24","Line":"前組2","SdNo":"S2602674","SdName":"特別養護老人ﾎｰﾑ","Floor":"3F","Symbol":"SD-31-4","ItemName":"親 枠 L","Qty":"1","StartTime":"17:45","EndTime":"18:15","Remark1":"森山と共同製作 作業時間合計25分","Remark2":"15100"},{"SchNo":"Q260824-0011","SchDate":"2026/08/24","Line":"前組2","SdNo":"S2602674","SdName":"特別養護老人ﾎｰﾑ","Floor":"4F","Symbol":"SD-31-4","ItemName":"親 枠 L","Qty":"1","StartTime":"18:20","EndTime":"18:50","Remark1":"森山へ","Remark2":"15100"},{"SchNo":"Q260824-0012","SchDate":"2026/08/24","Line":"前組4","SdNo":"S2602674","SdName":"特別養護老人ﾎｰﾑ","Floor":"2F","Symbol":"SD-31","ItemName":"親 枠 R","Qty":"1","StartTime":"8:40","EndTime":"9:30","Remark1":"下枠曲げ遅れにより中断","Remark2":""},{"SchNo":"Q260824-0013","SchDate":"2026/08/24","Line":"前組4","SdNo":"S2602674","SdName":"特別養護老人ﾎｰﾑ","Floor":"2F","Symbol":"SD-31","ItemName":"親 枠 R","Qty":"1","StartTime":"9:35","EndTime":"10:05","Remark1":"下枠曲げ遅れにより中断","Remark2":""},{"SchNo":"Q260824-0014","SchDate":"2026/08/24","Line":"前組4","SdNo":"S2602674","SdName":"特別養護老人ﾎｰﾑ","Floor":"2F","Symbol":"SD-31","ItemName":"親 枠 R","Qty":"1","StartTime":"10:10","EndTime":"10:45","Remark1":"下枠曲げ遅れにより中断","Remark2":""},{"SchNo":"Q260824-0015","SchDate":"2026/08/24","Line":"前組4","SdNo":"S2602674","SdName":"特別養護老人ﾎｰﾑ","Floor":"2F","Symbol":"SD-31","ItemName":"親 枠 L","Qty":"1","StartTime":"10:50","EndTime":"11:20","Remark1":"下枠曲げ遅れにより中断","Remark2":""},{"SchNo":"Q260824-0016","SchDate":"2026/08/24","Line":"前組4","SdNo":"S2602674","SdName":"特別養護老人ﾎｰﾑ","Floor":"3F","Symbol":"SD-31","ItemName":"親 枠 R","Qty":"1","StartTime":"11:25","EndTime":"11:55","Remark1":"下枠曲げ遅れにより中断","Remark2":""},{"SchNo":"Q260824-0017","SchDate":"2026/08/24","Line":"前組4","SdNo":"S2602674","SdName":"特別養護老人ﾎｰﾑ","Floor":"3F","Symbol":"SD-31","ItemName":"親 枠 R","Qty":"1","StartTime":"12:00","EndTime":"13:30","Remark1":"下枠曲げ遅れにより中断","Remark2":""},{"SchNo":"Q260824-0018","SchDate":"2026/08/24","Line":"前組4","SdNo":"S2602674","SdName":"特別養護老人ﾎｰﾑ","Floor":"3F","Symbol":"SD-31","ItemName":"親 枠 R","Qty":"1","StartTime":"13:35","EndTime":"14:05","Remark1":"下枠曲げ遅れにより中断","Remark2":""},{"SchNo":"Q260824-0019","SchDate":"2026/08/24","Line":"前組4","SdNo":"S2602674","SdName":"特別養護老人ﾎｰﾑ","Floor":"3F","Symbol":"SD-31","ItemName":"親 枠 L","Qty":"1","StartTime":"14:10","EndTime":"14:40","Remark1":"下枠曲げ遅れにより中断","Remark2":""},{"SchNo":"Q260824-0020","SchDate":"2026/08/24","Line":"前組4","SdNo":"S2602674","SdName":"特別養護老人ﾎｰﾑ","Floor":"4F","Symbol":"SD-31","ItemName":"親 枠 R","Qty":"1","StartTime":"14:45","EndTime":"15:30","Remark1":"下枠曲げ遅れにより中断","Remark2":""},{"SchNo":"Q260824-0021","SchDate":"2026/08/24","Line":"前組4","SdNo":"S2602674","SdName":"特別養護老人ﾎｰﾑ","Floor":"4F","Symbol":"SD-31","ItemName":"親 枠 R","Qty":"1","StartTime":"15:35","EndTime":"16:05","Remark1":"下枠曲げ遅れにより中断","Remark2":""},{"SchNo":"Q260824-0022","SchDate":"2026/08/24","Line":"前組4","SdNo":"S2602674","SdName":"特別養護老人ﾎｰﾑ","Floor":"4F","Symbol":"SD-31","ItemName":"親 枠 R","Qty":"1","StartTime":"16:10","EndTime":"16:40","Remark1":"下枠曲げ遅れにより中断","Remark2":""},{"SchNo":"Q260824-0023","SchDate":"2026/08/24","Line":"前組4","SdNo":"S2602674","SdName":"特別養護老人ﾎｰﾑ","Floor":"4F","Symbol":"SD-31","ItemName":"親 枠 L","Qty":"1","StartTime":"16:45","EndTime":"17:15","Remark1":"下枠曲げ遅れにより中断","Remark2":""},{"SchNo":"Q260824-0024","SchDate":"2026/08/24","Line":"前組4","SdNo":"S2602674","SdName":"特別養護老人ﾎｰﾑ","Floor":"2F","Symbol":"SD-31","ItemName":"親 枠 R","Qty":"0","StartTime":"17:15","EndTime":"17:15","Remark1":"作業時間合計55分","Remark2":"15100"},{"SchNo":"Q260824-0025","SchDate":"2026/08/24","Line":"前組4","SdNo":"S2602674","SdName":"特別養護老人ﾎｰﾑ","Floor":"2F","Symbol":"SD-31","ItemName":"親 枠 R","Qty":"0","StartTime":"17:15","EndTime":"17:15","Remark1":"作業時間合計20分","Remark2":"15100"},{"SchNo":"Q260824-0026","SchDate":"2026/08/24","Line":"前組4","SdNo":"S2602674","SdName":"特別養護老人ﾎｰﾑ","Floor":"2F","Symbol":"SD-31","ItemName":"親 枠 R","Qty":"0","StartTime":"17:15","EndTime":"17:15","Remark1":"作業時間合計30分","Remark2":"15100"},{"SchNo":"Q260824-0027","SchDate":"2026/08/24","Line":"前組4","SdNo":"S2602674","SdName":"特別養護老人ﾎｰﾑ","Floor":"2F","Symbol":"SD-31","ItemName":"親 枠 L","Qty":"0","StartTime":"17:15","EndTime":"17:15","Remark1":"作業時間合計25分","Remark2":"15100"},{"SchNo":"Q260824-0028","SchDate":"2026/08/24","Line":"前組4","SdNo":"S2602674","SdName":"特別養護老人ﾎｰﾑ","Floor":"3F","Symbol":"SD-31","ItemName":"親 枠 R","Qty":"0","StartTime":"17:15","EndTime":"17:15","Remark1":"作業時間合計20分","Remark2":"15100"},{"SchNo":"Q260824-0029","SchDate":"2026/08/24","Line":"前組4","SdNo":"S2602674","SdName":"特別養護老人ﾎｰﾑ","Floor":"3F","Symbol":"SD-31","ItemName":"親 枠 R","Qty":"0","StartTime":"17:15","EndTime":"17:15","Remark1":"作業時間合計25分","Remark2":"15100"},{"SchNo":"Q260824-0030","SchDate":"2026/08/24","Line":"前組4","SdNo":"S2602674","SdName":"特別養護老人ﾎｰﾑ","Floor":"3F","Symbol":"SD-31","ItemName":"親 枠 R","Qty":"0","StartTime":"17:15","EndTime":"17:15","Remark1":"作業時間合計20分","Remark2":"15100"},{"SchNo":"Q260824-0031","SchDate":"2026/08/24","Line":"前組4","SdNo":"S2602674","SdName":"特別養護老人ﾎｰﾑ","Floor":"3F","Symbol":"SD-31","ItemName":"親 枠 L","Qty":"0","StartTime":"17:15","EndTime":"17:15","Remark1":"作業時間合計25分","Remark2":"15100"},{"SchNo":"Q260824-0032","SchDate":"2026/08/24","Line":"前組4","SdNo":"S2602674","SdName":"特別養護老人ﾎｰﾑ","Floor":"4F","Symbol":"SD-31","ItemName":"親 枠 R","Qty":"0","StartTime":"17:15","EndTime":"17:15","Remark1":"作業時間合計30分","Remark2":"15100"},{"SchNo":"Q260824-0033","SchDate":"2026/08/24","Line":"前組4","SdNo":"S2602674","SdName":"特別養護老人ﾎｰﾑ","Floor":"4F","Symbol":"SD-31","ItemName":"親 枠 R","Qty":"0","StartTime":"17:15","EndTime":"17:15","Remark1":"作業時間合計20分","Remark2":"15100"},{"SchNo":"Q260824-0034","SchDate":"2026/08/24","Line":"前組4","SdNo":"S2602674","SdName":"特別養護老人ﾎｰﾑ","Floor":"4F","Symbol":"SD-31","ItemName":"親 枠 R","Qty":"0","StartTime":"17:15","EndTime":"17:15","Remark1":"作業時間合計15分","Remark2":"15100"},{"SchNo":"Q260824-0035","SchDate":"2026/08/24","Line":"前組4","SdNo":"S2602674","SdName":"特別養護老人ﾎｰﾑ","Floor":"4F","Symbol":"SD-31","ItemName":"親 枠 L","Qty":"0","StartTime":"17:15","EndTime":"17:15","Remark1":"作業時間合計20分","Remark2":"15100"},{"SchNo":"Q260824-0036","SchDate":"2026/08/24","Line":"前組4","SdNo":"S2602592","SdName":"TOK1__E__210-E520_I","Floor":"1F","Symbol":"E01SP-1A","ItemName":"親 枠 R","Qty":"1","StartTime":"17:35","EndTime":"18:15","Remark1":"","Remark2":"33000"},{"SchNo":"Q260824-0037","SchDate":"2026/08/24","Line":"前組4","SdNo":"S2602592","SdName":"TOK1__E__210-E520_I","Floor":"1F","Symbol":"E01SP-1A","ItemName":"親 枠 R","Qty":"1","StartTime":"18:25","EndTime":"19:05","Remark1":"","Remark2":"33000"},{"SchNo":"Q260824-0038","SchDate":"2026/08/24","Line":"前組4","SdNo":"S2602674","SdName":"特別養護老人ﾎｰﾑ","Floor":"2F","Symbol":"SD-31-4","ItemName":"親 枠 L","Qty":"0","StartTime":"19:05","EndTime":"19:05","Remark1":"小林分 小林と共同製作","Remark2":""},{"SchNo":"Q260824-0039","SchDate":"2026/08/24","Line":"前組4","SdNo":"S2602674","SdName":"特別養護老人ﾎｰﾑ","Floor":"3F","Symbol":"SD-31-4","ItemName":"親 枠 L","Qty":"0","StartTime":"19:05","EndTime":"19:05","Remark1":"小林分 小林と共同製作","Remark2":""},{"SchNo":"Q260824-0040","SchDate":"2026/08/24","Line":"前組4","SdNo":"S2602674","SdName":"特別養護老人ﾎｰﾑ","Floor":"4F","Symbol":"SD-31-4","ItemName":"親 枠 L","Qty":"0","StartTime":"19:05","EndTime":"19:05","Remark1":"小林分","Remark2":""},{"SchNo":"Q260824-0041","SchDate":"2026/08/24","Line":"前組6","SdNo":"S2602674","SdName":"特別養護老人ﾎｰﾑ","Floor":"2F","Symbol":"SD-31-2","ItemName":"親 枠 R","Qty":"1","StartTime":"8:40","EndTime":"9:30","Remark1":"下枠曲げ遅れにより中断","Remark2":""},{"SchNo":"Q260824-0042","SchDate":"2026/08/24","Line":"前組6","SdNo":"S2602674","SdName":"特別養護老人ﾎｰﾑ","Floor":"2F","Symbol":"SD-31-2","ItemName":"親 枠 R","Qty":"1","StartTime":"9:35","EndTime":"10:05","Remark1":"下枠曲げ遅れにより中断","Remark2":""},{"SchNo":"Q260824-0043","SchDate":"2026/08/24","Line":"前組6","SdNo":"S2602674","SdName":"特別養護老人ﾎｰﾑ","Floor":"2F","Symbol":"SD-31-2","ItemName":"親 枠 L","Qty":"1","StartTime":"10:10","EndTime":"10:45","Remark1":"下枠曲げ遅れにより中断","Remark2":""},{"SchNo":"Q260824-0044","SchDate":"2026/08/24","Line":"前組6","SdNo":"S2602674","SdName":"特別養護老人ﾎｰﾑ","Floor":"2F","Symbol":"SD-31-2","ItemName":"親 枠 L","Qty":"1","StartTime":"10:50","EndTime":"11:20","Remark1":"下枠曲げ遅れにより中断","Remark2":""},{"SchNo":"Q260824-0045","SchDate":"2026/08/24","Line":"前組6","SdNo":"S2602674","SdName":"特別養護老人ﾎｰﾑ","Floor":"3F","Symbol":"SD-31-2","ItemName":"親 枠 R","Qty":"1","StartTime":"11:25","EndTime":"11:55","Remark1":"下枠曲げ遅れにより中断","Remark2":""},{"SchNo":"Q260824-0046","SchDate":"2026/08/24","Line":"前組6","SdNo":"S2602674","SdName":"特別養護老人ﾎｰﾑ","Floor":"3F","Symbol":"SD-31-2","ItemName":"親 枠 R","Qty":"1","StartTime":"12:00","EndTime":"13:30","Remark1":"下枠曲げ遅れにより中断","Remark2":""},{"SchNo":"Q260824-0047","SchDate":"2026/08/24","Line":"前組6","SdNo":"S2602674","SdName":"特別養護老人ﾎｰﾑ","Floor":"3F","Symbol":"SD-31-2","ItemName":"親 枠 L","Qty":"1","StartTime":"13:35","EndTime":"14:05","Remark1":"下枠曲げ遅れにより中断","Remark2":""},{"SchNo":"Q260824-0048","SchDate":"2026/08/24","Line":"前組6","SdNo":"S2602674","SdName":"特別養護老人ﾎｰﾑ","Floor":"2F","Symbol":"SD-31-2","ItemName":"親 枠 R","Qty":"0","StartTime":"14:05","EndTime":"14:05","Remark1":"作業時間合計105分","Remark2":"17900"},{"SchNo":"Q260824-0049","SchDate":"2026/08/24","Line":"前組6","SdNo":"S2602674","SdName":"特別養護老人ﾎｰﾑ","Floor":"2F","Symbol":"SD-31-2","ItemName":"親 枠 R","Qty":"0","StartTime":"14:05","EndTime":"14:05","Remark1":"作業時間合計30分","Remark2":"17900"},{"SchNo":"Q260824-0050","SchDate":"2026/08/24","Line":"前組6","SdNo":"S2602674","SdName":"特別養護老人ﾎｰﾑ","Floor":"2F","Symbol":"SD-31-2","ItemName":"親 枠 L","Qty":"0","StartTime":"14:05","EndTime":"14:05","Remark1":"作業時間合計30分","Remark2":"17900"},{"SchNo":"Q260824-0051","SchDate":"2026/08/24","Line":"前組6","SdNo":"S2602674","SdName":"特別養護老人ﾎｰﾑ","Floor":"2F","Symbol":"SD-31-2","ItemName":"親 枠 L","Qty":"0","StartTime":"14:05","EndTime":"14:05","Remark1":"作業時間合計45分","Remark2":"17900"},{"SchNo":"Q260824-0052","SchDate":"2026/08/24","Line":"前組6","SdNo":"S2602674","SdName":"特別養護老人ﾎｰﾑ","Floor":"3F","Symbol":"SD-31-2","ItemName":"親 枠 R","Qty":"0","StartTime":"14:05","EndTime":"14:05","Remark1":"作業時間合計35分","Remark2":"17900"},{"SchNo":"Q260824-0053","SchDate":"2026/08/24","Line":"前組6","SdNo":"S2602674","SdName":"特別養護老人ﾎｰﾑ","Floor":"3F","Symbol":"SD-31-2","ItemName":"親 枠 R","Qty":"0","StartTime":"14:05","EndTime":"14:05","Remark1":"作業時間合計30分","Remark2":"17900"},{"SchNo":"Q260824-0054","SchDate":"2026/08/24","Line":"前組6","SdNo":"S2602674","SdName":"特別養護老人ﾎｰﾑ","Floor":"3F","Symbol":"SD-31-2","ItemName":"親 枠 L","Qty":"0","StartTime":"14:05","EndTime":"14:05","Remark1":"作業時間合計30分","Remark2":"17900"},{"SchNo":"Q260824-0055","SchDate":"2026/08/24","Line":"前組6","SdNo":"S2602674","SdName":"特別養護老人ﾎｰﾑ","Floor":"3F","Symbol":"SD-31-2","ItemName":"親 枠 L","Qty":"1","StartTime":"14:10","EndTime":"14:40","Remark1":"下枠曲げ遅れにより中断","Remark2":""},{"SchNo":"Q260824-0056","SchDate":"2026/08/24","Line":"前組6","SdNo":"S2602674","SdName":"特別養護老人ﾎｰﾑ","Floor":"4F","Symbol":"SD-31-2","ItemName":"親 枠 R","Qty":"1","StartTime":"14:45","EndTime":"15:30","Remark1":"下枠曲げ遅れにより中断","Remark2":""},{"SchNo":"Q260824-0057","SchDate":"2026/08/24","Line":"前組6","SdNo":"S2602674","SdName":"特別養護老人ﾎｰﾑ","Floor":"4F","Symbol":"SD-31-2","ItemName":"親 枠 R","Qty":"1","StartTime":"15:35","EndTime":"16:05","Remark1":"下枠曲げ遅れにより中断","Remark2":""},{"SchNo":"Q260824-0058","SchDate":"2026/08/24","Line":"前組6","SdNo":"S2602674","SdName":"特別養護老人ﾎｰﾑ","Floor":"3F","Symbol":"SD-31-2","ItemName":"親 枠 L","Qty":"0","StartTime":"16:05","EndTime":"16:05","Remark1":"作業時間合計35分","Remark2":"17900"},{"SchNo":"Q260824-0059","SchDate":"2026/08/24","Line":"前組6","SdNo":"S2602674","SdName":"特別養護老人ﾎｰﾑ","Floor":"4F","Symbol":"SD-31-2","ItemName":"親 枠 R","Qty":"0","StartTime":"16:05","EndTime":"16:05","Remark1":"作業時間合計30分","Remark2":"17900"},{"SchNo":"Q260824-0060","SchDate":"2026/08/24","Line":"前組6","SdNo":"S2602674","SdName":"特別養護老人ﾎｰﾑ","Floor":"4F","Symbol":"SD-31-2","ItemName":"親 枠 R","Qty":"0","StartTime":"16:05","EndTime":"16:05","Remark1":"作業時間合計30分","Remark2":"17900"},{"SchNo":"Q260824-0061","SchDate":"2026/08/24","Line":"前組6","SdNo":"S2602674","SdName":"特別養護老人ﾎｰﾑ","Floor":"4F","Symbol":"SD-31-2","ItemName":"親 枠 L","Qty":"1","StartTime":"16:10","EndTime":"16:40","Remark1":"","Remark2":"17900"},{"SchNo":"Q260824-0062","SchDate":"2026/08/24","Line":"前組6","SdNo":"S2602674","SdName":"特別養護老人ﾎｰﾑ","Floor":"4F","Symbol":"SD-31-2","ItemName":"親 枠 L","Qty":"1","StartTime":"16:45","EndTime":"17:15","Remark1":"","Remark2":"17900"},{"SchNo":"Q260824-0063","SchDate":"2026/08/24","Line":"前組6","SdNo":"S2602592","SdName":"TOK1__E__210-E520_I","Floor":"1F","Symbol":"E01SP-1","ItemName":"親 枠 R","Qty":"0","StartTime":"17:15","EndTime":"17:15","Remark1":"本組春木分","Remark2":""},{"SchNo":"Q260824-0064","SchDate":"2026/08/24","Line":"前組6","SdNo":"S2602592","SdName":"TOK1__E__210-E520_I","Floor":"1F","Symbol":"E01SP-1","ItemName":"親 枠 R","Qty":"0","StartTime":"17:15","EndTime":"17:15","Remark1":"本組春木分","Remark2":""},{"SchNo":"Q260824-0065","SchDate":"2026/08/24","Line":"前組6","SdNo":"S2602592","SdName":"TOK1__E__210-E520_I","Floor":"1F","Symbol":"E01SP-1A","ItemName":"親 枠 R","Qty":"0","StartTime":"17:15","EndTime":"17:15","Remark1":"木村分","Remark2":""},{"SchNo":"Q260824-0066","SchDate":"2026/08/24","Line":"前組6","SdNo":"S2602592","SdName":"TOK1__E__210-E520_I","Floor":"1F","Symbol":"E01SP-1A","ItemName":"親 枠 R","Qty":"1","StartTime":"17:35","EndTime":"18:15","Remark1":"","Remark2":"33000"},{"SchNo":"Q260824-0067","SchDate":"2026/08/24","Line":"前組7","SdNo":"S2602671","SdName":"所沢市小手指一丁目計画","Floor":"2F","Symbol":"SD-213","ItemName":"親 枠 L","Qty":"1","StartTime":"8:40","EndTime":"13:05","Remark1":"曲げ未完了により中断","Remark2":""},{"SchNo":"Q260824-0068","SchDate":"2026/08/24","Line":"前組7","SdNo":"S2602671","SdName":"所沢市小手指一丁目計画","Floor":"2F","Symbol":"SD-253","ItemName":"親 枠 R","Qty":"1","StartTime":"13:25","EndTime":"16:40","Remark1":"","Remark2":"110700"},{"SchNo":"Q260824-0069","SchDate":"2026/08/24","Line":"前組7","SdNo":"S2602671","SdName":"所沢市小手指一丁目計画","Floor":"2F","Symbol":"SD-213","ItemName":"親 枠 L","Qty":"0","StartTime":"16:40","EndTime":"16:40","Remark1":"作業時間合計240分","Remark2":"109900"},{"SchNo":"Q260824-0070","SchDate":"2026/08/24","Line":"前組7","SdNo":"S2602674","SdName":"特別養護老人ﾎｰﾑ","Floor":"2F","Symbol":"SD-31A","ItemName":"親 枠 R","Qty":"1","StartTime":"17:00","EndTime":"17:40","Remark1":"","Remark2":"21600"},{"SchNo":"Q260824-0071","SchDate":"2026/08/24","Line":"前組7","SdNo":"S2602674","SdName":"特別養護老人ﾎｰﾑ","Floor":"3F","Symbol":"SD-31A","ItemName":"親 枠 R","Qty":"1","StartTime":"17:45","EndTime":"18:15","Remark1":"","Remark2":"21600"},{"SchNo":"Q260824-0072","SchDate":"2026/08/24","Line":"前組7","SdNo":"S2602674","SdName":"特別養護老人ﾎｰﾑ","Floor":"4F","Symbol":"SD-31A","ItemName":"親 枠 R","Qty":"1","StartTime":"18:20","EndTime":"18:50","Remark1":"","Remark2":"21600"},{"SchNo":"Q260824-0073","SchDate":"2026/08/24","Line":"前組7","SdNo":"S2602592","SdName":"TOK1__E__210-E520_I","Floor":"1F","Symbol":"E01SP-1A","ItemName":"親 枠 R","Qty":"1","StartTime":"19:00","EndTime":"19:50","Remark1":"吉田へ","Remark2":"33000"}]
A2: ="Q"&TEXT(B2,"yyMMdd")&"-"&TEXT(ROW(),"0000") -> Q260824-0002 | B2: =TEXT(Sheet2!A2,"yyyy/MM/dd") -> 2026/08/24 | C2: =Sheet2!B2&"" -> 前組2 | D2: =Sheet2!C2&"" -> S2602671 | E2: =Sheet2!D2&"" -> 所沢市小手指一丁目計画 | F2: =Sheet2!E2&"" -> 1F | G2: =Sheet2!F2&"" -> SD-115 | H2: =_xlfn.TEXTJOIN(" ",TRUE,Sheet2!G2,Sheet2!H2,Sheet2!I2) -> 親 枠 R | I2: =Sheet2!J2 -> 1 | J2: =Sheet2!K2&"" -> 8:40 | K2: =Sheet2!L2&"" -> 11:05 | L2: =Sheet2!M2&"" -> 曲げ遅れにより中断 | M2: =Sheet2!N2&"" | N2: {="{"&_xlfn.TEXTJOIN(",",FALSE,""""&ASC($A$1:$M$1)&""""&":"&""""&ASC(A2:M2)&"""")&"}"} -> {"SchNo":"Q260824-0002","SchDate":"2026/08/24","Line":"前組2","SdNo":"S2602671","SdName":"所沢市小手指一丁目計画","Floor":"1F","Symbol":"SD-115","ItemName":"親 枠 R","Qty":"1","StartTime":"8:40","EndTime":"11:05","Remark1":"曲げ遅れにより中断","Remark2":""}
A3: ="Q"&TEXT(B3,"yyMMdd")&"-"&TEXT(ROW(),"0000") -> Q260824-0003 | B3: =TEXT(Sheet2!A3,"yyyy/MM/dd") -> 2026/08/24 | C3: =Sheet2!B3&"" -> 前組2 | D3: =Sheet2!C3&"" -> S2602671 | E3: =Sheet2!D3&"" -> 所沢市小手指一丁目計画 | F3: =Sheet2!E3&"" -> 3F | G3: =Sheet2!F3&"" -> SD-301 | H3: =_xlfn.TEXTJOIN(" ",TRUE,Sheet2!G3,Sheet2!H3,Sheet2!I3) -> 親 枠 L | I3: =Sheet2!J3 -> 1 | J3: =Sheet2!K3&"" -> 11:25 | K3: =Sheet2!L3&"" -> 14:25 | L3: =Sheet2!M3&"" -> 曲げ遅れにより中断 | M3: =Sheet2!N3&"" | N3: {="{"&_xlfn.TEXTJOIN(",",FALSE,""""&ASC($A$1:$M$1)&""""&":"&""""&ASC(A3:M3)&"""")&"}"} -> {"SchNo":"Q260824-0003","SchDate":"2026/08/24","Line":"前組2","SdNo":"S2602671","SdName":"所沢市小手指一丁目計画","Floor":"3F","Symbol":"SD-301","ItemName":"親 枠 L","Qty":"1","StartTime":"11:25","EndTime":"14:25","Remark1":"曲げ遅れにより中断","Remark2":""}
A4: ="Q"&TEXT(B4,"yyMMdd")&"-"&TEXT(ROW(),"0000") -> Q260824-0004 | B4: =TEXT(Sheet2!A4,"yyyy/MM/dd") -> 2026/08/24 | C4: =Sheet2!B4&"" -> 前組2 | D4: =Sheet2!C4&"" -> S2602674 | E4: =Sheet2!D4&"" -> 特別養護老人ホーム | F4: =Sheet2!E4&"" -> 2F | G4: =Sheet2!F4&"" -> SD-31-1 | H4: =_xlfn.TEXTJOIN(" ",TRUE,Sheet2!G4,Sheet2!H4,Sheet2!I4) -> 親 枠 R | I4: =Sheet2!J4 -> 1 | J4: =Sheet2!K4&"" -> 14:45 | K4: =Sheet2!L4&"" -> 15:30 | L4: =Sheet2!M4&"" -> 作業者に指示出し等で段取り時間増 | M4: =Sheet2!N4&"" -> 15600 | N4: {="{"&_xlfn.TEXTJOIN(",",FALSE,""""&ASC($A$1:$M$1)&""""&":"&""""&ASC(A4:M4)&"""")&"}"} -> {"SchNo":"Q260824-0004","SchDate":"2026/08/24","Line":"前組2","SdNo":"S2602674","SdName":"特別養護老人ﾎｰﾑ","Floor":"2F","Symbol":"SD-31-1","ItemName":"親 枠 R","Qty":"1","StartTime":"14:45","EndTime":"15:30","Remark1":"作業者に指示出し等で段取り時間増","Remark2":"15600"}
A5: ="Q"&TEXT(B5,"yyMMdd")&"-"&TEXT(ROW(),"0000") -> Q260824-0005 | B5: =TEXT(Sheet2!A5,"yyyy/MM/dd") -> 2026/08/24 | C5: =Sheet2!B5&"" -> 前組2 | D5: =Sheet2!C5&"" -> S2602671 | E5: =Sheet2!D5&"" -> 所沢市小手指一丁目計画 | F5: =Sheet2!E5&"" -> 1F | G5: =Sheet2!F5&"" -> SD-115 | H5: =_xlfn.TEXTJOIN(" ",TRUE,Sheet2!G5,Sheet2!H5,Sheet2!I5) -> 親 枠 R | I5: =Sheet2!J5 -> 0 | J5: =Sheet2!K5&"" -> 15:30 | K5: =Sheet2!L5&"" -> 15:30 | L5: =Sheet2!M5&"" -> 作業時間合計95分 | M5: =Sheet2!N5&"" -> 78000 | N5: {="{"&_xlfn.TEXTJOIN(",",FALSE,""""&ASC($A$1:$M$1)&""""&":"&""""&ASC(A5:M5)&"""")&"}"} -> {"SchNo":"Q260824-0005","SchDate":"2026/08/24","Line":"前組2","SdNo":"S2602671","SdName":"所沢市小手指一丁目計画","Floor":"1F","Symbol":"SD-115","ItemName":"親 枠 R","Qty":"0","StartTime":"15:30","EndTime":"15:30","Remark1":"作業時間合計95分","Remark2":"78000"}
A6: ="Q"&TEXT(B6,"yyMMdd")&"-"&TEXT(ROW(),"0000") -> Q260824-0006 | B6: =TEXT(Sheet2!A6,"yyyy/MM/dd") -> 2026/08/24 | C6: =Sheet2!B6&"" -> 前組2 | D6: =Sheet2!C6&"" -> S2602671 | E6: =Sheet2!D6&"" -> 所沢市小手指一丁目計画 | F6: =Sheet2!E6&"" -> 3F | G6: =Sheet2!F6&"" -> SD-301 | H6: =_xlfn.TEXTJOIN(" ",TRUE,Sheet2!G6,Sheet2!H6,Sheet2!I6) -> 親 枠 L | I6: =Sheet2!J6 -> 0 | J6: =Sheet2!K6&"" -> 15:30 | K6: =Sheet2!L6&"" -> 15:30 | L6: =Sheet2!M6&"" -> 作業時間合計115分 | M6: =Sheet2!N6&"" -> 73800 | N6: {="{"&_xlfn.TEXTJOIN(",",FALSE,""""&ASC($A$1:$M$1)&""""&":"&""""&ASC(A6:M6)&"""")&"}"} -> {"SchNo":"Q260824-0006","SchDate":"2026/08/24","Line":"前組2","SdNo":"S2602671","SdName":"所沢市小手指一丁目計画","Floor":"3F","Symbol":"SD-301","ItemName":"親 枠 L","Qty":"0","StartTime":"15:30","EndTime":"15:30","Remark1":"作業時間合計115分","Remark2":"73800"}
A7: ="Q"&TEXT(B7,"yyMMdd")&"-"&TEXT(ROW(),"0000") -> Q260824-0007 | B7: =TEXT(Sheet2!A7,"yyyy/MM/dd") -> 2026/08/24 | C7: =Sheet2!B7&"" -> 前組2 | D7: =Sheet2!C7&"" -> S2602674 | E7: =Sheet2!D7&"" -> 特別養護老人ホーム | F7: =Sheet2!E7&"" -> 3F | G7: =Sheet2!F7&"" -> SD-31-1 | H7: =_xlfn.TEXTJOIN(" ",TRUE,Sheet2!G7,Sheet2!H7,Sheet2!I7) -> 親 枠 R | I7: =Sheet2!J7 -> 1 | J7: =Sheet2!K7&"" -> 15:35 | K7: =Sheet2!L7&"" -> 16:05 | L7: =Sheet2!M7&"" | M7: =Sheet2!N7&"" -> 15600 | N7: {="{"&_xlfn.TEXTJOIN(",",FALSE,""""&ASC($A$1:$M$1)&""""&":"&""""&ASC(A7:M7)&"""")&"}"} -> {"SchNo":"Q260824-0007","SchDate":"2026/08/24","Line":"前組2","SdNo":"S2602674","SdName":"特別養護老人ﾎｰﾑ","Floor":"3F","Symbol":"SD-31-1","ItemName":"親 枠 R","Qty":"1","StartTime":"15:35","EndTime":"16:05","Remark1":"","Remark2":"15600"}
A8: ="Q"&TEXT(B8,"yyMMdd")&"-"&TEXT(ROW(),"0000") -> Q260824-0008 | B8: =TEXT(Sheet2!A8,"yyyy/MM/dd") -> 2026/08/24 | C8: =Sheet2!B8&"" -> 前組2 | D8: =Sheet2!C8&"" -> S2602674 | E8: =Sheet2!D8&"" -> 特別養護老人ホーム | F8: =Sheet2!E8&"" -> 4F | G8: =Sheet2!F8&"" -> SD-31-1 | H8: =_xlfn.TEXTJOIN(" ",TRUE,Sheet2!G8,Sheet2!H8,Sheet2!I8) -> 親 枠 R | I8: =Sheet2!J8 -> 1 | J8: =Sheet2!K8&"" -> 16:10 | K8: =Sheet2!L8&"" -> 16:40 | L8: =Sheet2!M8&"" | M8: =Sheet2!N8&"" -> 15600 | N8: {="{"&_xlfn.TEXTJOIN(",",FALSE,""""&ASC($A$1:$M$1)&""""&":"&""""&ASC(A8:M8)&"""")&"}"} -> {"SchNo":"Q260824-0008","SchDate":"2026/08/24","Line":"前組2","SdNo":"S2602674","SdName":"特別養護老人ﾎｰﾑ","Floor":"4F","Symbol":"SD-31-1","ItemName":"親 枠 R","Qty":"1","StartTime":"16:10","EndTime":"16:40","Remark1":"","Remark2":"15600"}
A9: ="Q"&TEXT(B9,"yyMMdd")&"-"&TEXT(ROW(),"0000") -> Q260824-0009 | B9: =TEXT(Sheet2!A9,"yyyy/MM/dd") -> 2026/08/24 | C9: =Sheet2!B9&"" -> 前組2 | D9: =Sheet2!C9&"" -> S2602674 | E9: =Sheet2!D9&"" -> 特別養護老人ホーム | F9: =Sheet2!E9&"" -> 2F | G9: =Sheet2!F9&"" -> SD-31-4 | H9: =_xlfn.TEXTJOIN(" ",TRUE,Sheet2!G9,Sheet2!H9,Sheet2!I9) -> 親 枠 L | I9: =Sheet2!J9 -> 1 | J9: =Sheet2!K9&"" -> 17:00 | K9: =Sheet2!L9&"" -> 17:40 | L9: =Sheet2!M9&"" -> 森山と共同製作 作業時間合計25分 | M9: =Sheet2!N9&"" -> 15100 | N9: {="{"&_xlfn.TEXTJOIN(",",FALSE,""""&ASC($A$1:$M$1)&""""&":"&""""&ASC(A9:M9)&"""")&"}"} -> {"SchNo":"Q260824-0009","SchDate":"2026/08/24","Line":"前組2","SdNo":"S2602674","SdName":"特別養護老人ﾎｰﾑ","Floor":"2F","Symbol":"SD-31-4","ItemName":"親 枠 L","Qty":"1","StartTime":"17:00","EndTime":"17:40","Remark1":"森山と共同製作 作業時間合計25分","Remark2":"15100"}
A10: ="Q"&TEXT(B10,"yyMMdd")&"-"&TEXT(ROW(),"0000") -> Q260824-0010 | B10: =TEXT(Sheet2!A10,"yyyy/MM/dd") -> 2026/08/24 | C10: =Sheet2!B10&"" -> 前組2 | D10: =Sheet2!C10&"" -> S2602674 | E10: =Sheet2!D10&"" -> 特別養護老人ホーム | F10: =Sheet2!E10&"" -> 3F | G10: =Sheet2!F10&"" -> SD-31-4 | H10: =_xlfn.TEXTJOIN(" ",TRUE,Sheet2!G10,Sheet2!H10,Sheet2!I10) -> 親 枠 L | I10: =Sheet2!J10 -> 1 | J10: =Sheet2!K10&"" -> 17:45 | K10: =Sheet2!L10&"" -> 18:15 | L10: =Sheet2!M10&"" -> 森山と共同製作 作業時間合計25分 | M10: =Sheet2!N10&"" -> 15100 | N10: {="{"&_xlfn.TEXTJOIN(",",FALSE,""""&ASC($A$1:$M$1)&""""&":"&""""&ASC(A10:M10)&"""")&"}"} -> {"SchNo":"Q260824-0010","SchDate":"2026/08/24","Line":"前組2","SdNo":"S2602674","SdName":"特別養護老人ﾎｰﾑ","Floor":"3F","Symbol":"SD-31-4","ItemName":"親 枠 L","Qty":"1","StartTime":"17:45","EndTime":"18:15","Remark1":"森山と共同製作 作業時間合計25分","Remark2":"15100"}
A11: ="Q"&TEXT(B11,"yyMMdd")&"-"&TEXT(ROW(),"0000") -> Q260824-0011 | B11: =TEXT(Sheet2!A11,"yyyy/MM/dd") -> 2026/08/24 | C11: =Sheet2!B11&"" -> 前組2 | D11: =Sheet2!C11&"" -> S2602674 | E11: =Sheet2!D11&"" -> 特別養護老人ホーム | F11: =Sheet2!E11&"" -> 4F | G11: =Sheet2!F11&"" -> SD-31-4 | H11: =_xlfn.TEXTJOIN(" ",TRUE,Sheet2!G11,Sheet2!H11,Sheet2!I11) -> 親 枠 L | I11: =Sheet2!J11 -> 1 | J11: =Sheet2!K11&"" -> 18:20 | K11: =Sheet2!L11&"" -> 18:50 | L11: =Sheet2!M11&"" -> 森山へ | M11: =Sheet2!N11&"" -> 15100 | N11: {="{"&_xlfn.TEXTJOIN(",",FALSE,""""&ASC($A$1:$M$1)&""""&":"&""""&ASC(A11:M11)&"""")&"}"} -> {"SchNo":"Q260824-0011","SchDate":"2026/08/24","Line":"前組2","SdNo":"S2602674","SdName":"特別養護老人ﾎｰﾑ","Floor":"4F","Symbol":"SD-31-4","ItemName":"親 枠 L","Qty":"1","StartTime":"18:20","EndTime":"18:50","Remark1":"森山へ","Remark2":"15100"}
A12: ="Q"&TEXT(B12,"yyMMdd")&"-"&TEXT(ROW(),"0000") -> Q260824-0012 | B12: =TEXT(Sheet2!A12,"yyyy/MM/dd") -> 2026/08/24 | C12: =Sheet2!B12&"" -> 前組4 | D12: =Sheet2!C12&"" -> S2602674 | E12: =Sheet2!D12&"" -> 特別養護老人ホーム | F12: =Sheet2!E12&"" -> 2F | G12: =Sheet2!F12&"" -> SD-31 | H12: =_xlfn.TEXTJOIN(" ",TRUE,Sheet2!G12,Sheet2!H12,Sheet2!I12) -> 親 枠 R | I12: =Sheet2!J12 -> 1 | J12: =Sheet2!K12&"" -> 8:40 | K12: =Sheet2!L12&"" -> 9:30 | L12: =Sheet2!M12&"" -> 下枠曲げ遅れにより中断 | M12: =Sheet2!N12&"" | N12: {="{"&_xlfn.TEXTJOIN(",",FALSE,""""&ASC($A$1:$M$1)&""""&":"&""""&ASC(A12:M12)&"""")&"}"} -> {"SchNo":"Q260824-0012","SchDate":"2026/08/24","Line":"前組4","SdNo":"S2602674","SdName":"特別養護老人ﾎｰﾑ","Floor":"2F","Symbol":"SD-31","ItemName":"親 枠 R","Qty":"1","StartTime":"8:40","EndTime":"9:30","Remark1":"下枠曲げ遅れにより中断","Remark2":""}
A13: ="Q"&TEXT(B13,"yyMMdd")&"-"&TEXT(ROW(),"0000") -> Q260824-0013 | B13: =TEXT(Sheet2!A13,"yyyy/MM/dd") -> 2026/08/24 | C13: =Sheet2!B13&"" -> 前組4 | D13: =Sheet2!C13&"" -> S2602674 | E13: =Sheet2!D13&"" -> 特別養護老人ホーム | F13: =Sheet2!E13&"" -> 2F | G13: =Sheet2!F13&"" -> SD-31 | H13: =_xlfn.TEXTJOIN(" ",TRUE,Sheet2!G13,Sheet2!H13,Sheet2!I13) -> 親 枠 R | I13: =Sheet2!J13 -> 1 | J13: =Sheet2!K13&"" -> 9:35 | K13: =Sheet2!L13&"" -> 10:05 | L13: =Sheet2!M13&"" -> 下枠曲げ遅れにより中断 | M13: =Sheet2!N13&"" | N13: {="{"&_xlfn.TEXTJOIN(",",FALSE,""""&ASC($A$1:$M$1)&""""&":"&""""&ASC(A13:M13)&"""")&"}"} -> {"SchNo":"Q260824-0013","SchDate":"2026/08/24","Line":"前組4","SdNo":"S2602674","SdName":"特別養護老人ﾎｰﾑ","Floor":"2F","Symbol":"SD-31","ItemName":"親 枠 R","Qty":"1","StartTime":"9:35","EndTime":"10:05","Remark1":"下枠曲げ遅れにより中断","Remark2":""}
... A73: ="Q"&TEXT(B73,"yyMMdd")&"-"&TEXT(ROW(),"0000") -> Q260824-0073 | B73: =TEXT(Sheet2!A73,"yyyy/MM/dd") -> 2026/08/24 | C73: =Sheet2!B73&"" -> 前組7 | D73: =Sheet2!C73&"" -> S2602592 | E73: =Sheet2!D73&"" -> TOK1__E__210-E520＿I | F73: =Sheet2!E73&"" -> 1F | G73: =Sheet2!F73&"" -> E01SP-1A | H73: =_xlfn.TEXTJOIN(" ",TRUE,Sheet2!G73,Sheet2!H73,Sheet2!I73) -> 親 枠 R | I73: =Sheet2!J73 -> 1 | J73: =Sheet2!K73&"" -> 19:00 | K73: =Sheet2!L73&"" -> 19:50 | L73: =Sheet2!M73&"" -> 吉田へ | M73: =Sheet2!N73&"" -> 33000 | N73: {="{"&_xlfn.TEXTJOIN(",",FALSE,""""&ASC($A$1:$M$1)&""""&":"&""""&ASC(A73:M73)&"""")&"}"} -> {"SchNo":"Q260824-0073","SchDate":"2026/08/24","Line":"前組7","SdNo":"S2602592","SdName":"TOK1__E__210-E520_I","Floor":"1F","Symbol":"E01SP-1A","ItemName":"親 枠 R","Qty":"1","StartTime":"19:00","EndTime":"19:50","Remark1":"吉田へ","Remark2":"33000"}
